Workbook

Sheet 2025 RAC
A1: 日期 | B1: PI | C1: 型号 | D1: 数量 | E1: Contr # | F1: 客户Req date/需求ETD | G1: Actual ETD | H1: ETA | I1: 发票号 | J1: Destination | K1: Customer | L1: 清关资料 | M1: Remark
A2: 2024.10.31 | B2: PINMEL20241101022 | C2: MFAG26VA-N | D2: 25 | E2: RAC-025/ TGBU4948334 | G2: =VLOOKUP(CLEAN(SUBSTITUTE(TRIM(MID(E:E,FIND("/",E:E)+1,LEN(E:E)))," ","")),'Customs Decl. & Local Delivery'!D:I,6,0) -> 45656 | H2: =VLOOKUP(CLEAN(SUBSTITUTE(TRIM(MID(E:E,FIND("/",E:E)+1,LEN(E:E)))," ","")),'Customs Decl. & Local Delivery'!D:J,7,0) -> 45682 | I2: MDAJB241230D0005 | J2: VIC-Mel | K2: Polyaire | L2: Y | M2: polyaire PO #34610
A3: 2024.10.31 | B3: PINMEL20241101022 | C3: MFAG26VA-W | D3: 25 | G3: =G2 -> 45656 | H3: =H2 -> 45682 | I3: MDAJB241230D0005 | J3: VIC-Mel | K3: Polyaire | L3: Y | M3: REQ DATE:2024/ 1/23
A4: 2024.10.31 | B4: PINMEL20241101022 | C4: MFAG36VA-N | D4: 14 | G4: =G3 -> 45656 | H4: =H3 -> 45682 | I4: MDAJB241230D0005 | J4: VIC-Mel | K4: Polyaire | L4: Y
A5: 2024.10.31 | B5: PINMEL20241101022 | C5: MFAG36VA-W | D5: 14 | G5: =G4 -> 45656 | H5: =H4 -> 45682 | I5: MDAJB241230D0005 | J5: VIC-Mel | K5: Polyaire | L5: Y | M5: RAC CIF 928, POL-Beijiao, OOCL, LFD 21
A6: 2024.10.31 | B6: PINMEL20241101022 | C6: MFAG51VA-N | D6: 10 | G6: =G5 -> 45656 | H6: =H5 -> 45682 | I6: MDAJB241230D0005 | J6: VIC-Mel | K6: Polyaire | L6: Y
A7: 2024.10.31 | B7: PINMEL20241101022 | C7: MFAG51VA-W | D7: 10 | G7: =G6 -> 45656 | H7: =H6 -> 45682 | I7: MDAJB241230D0005 | J7: VIC-Mel | K7: Polyaire | L7: Y
A8: 2024.10.31 | B8: PINMEL20241101022 | C8: DUCMI105IHB | D8: 3 | G8: =G7 -> 45656 | H8: =H7 -> 45682 | I8: MDAJB241230D0005 | J8: VIC-Mel | K8: Polyaire | L8: Y
A9: 2024.10.31 | B9: PINMEL20241101022 | C9: UCMI105OB | D9: 3 | G9: =G8 -> 45656 | H9: =H8 -> 45682 | I9: MDAJB241230D0005 | J9: VIC-Mel | K9: Polyaire | L9: Y
A10: 2024.10.31 | B10: PINMEL20241101022 | C10: DUCMI125IHB | D10: 7 | G10: =G9 -> 45656 | H10: =H9 -> 45682 | I10: MDAJB241230D0005 | J10: VIC-Mel | K10: Polyaire | L10: Y
A11: 2024.10.31 | B11: PINMEL20241101022 | C11: UCMI125OB | D11: 7 | G11: =G10 -> 45656 | H11: =H10 -> 45682 | I11: MDAJB241230D0005 | J11: VIC-Mel | K11: Polyaire | L11: Y
A12: 2024.10.31 | B12: PINMEL20241101022 | C12: DUCMI140IHB | D12: 27 | G12: =G11 -> 45656 | H12: =H11 -> 45682 | I12: MDAJB241230D0005 | J12: VIC-Mel | K12: Polyaire | L12: Y
A13: 2024.10.31 | B13: PINMEL20241101022 | C13: UCMI140OB | D13: 27 | G13: =G12 -> 45656 | H13: =H12 -> 45682 | I13: MDAJB241230D0005 | J13: VIC-Mel | K13: Polyaire | L13: Y
A14: 2024.10.31 | B14: PINBRI20241101024 | C14: MFAB-26NC | D14: 50 | E14: RAC-001/ FSCU7105661 | G14: =VLOOKUP(CLEAN(SUBSTITUTE(TRIM(MID(E:E,FIND("/",E:E)+1,LEN(E:E)))," ","")),'Customs Decl. & Local Delivery'!D:I,6,0) -> 45660 | H14: =VLOOKUP(CLEAN(SUBSTITUTE(TRIM(MID(E:E,FIND("/",E:E)+1,LEN(E:E)))," ","")),'Customs Decl. & Local Delivery'!D:J,7,0) -> 45696 | I14: MDAJB250102D0049 | J14: QLD-Brisbane | K14: Polyaire | L14: Y | M14: polyaire PO #34622
A15: 2024.10.31 | B15: PINBRI20241101024 | C15: MFAB-26WC | D15: 50 | G15: =G14 -> 45660 | H15: =H14 -> 45696 | I15: MDAJB250102D0049 | J15: QLD-Brisbane | K15: Polyaire | L15: Y | M15: REQ DATE:2025/1/23
A16: 2024.10.31 | B16: PINBRI20241101024 | C16: MFAB-35NC | D16: 20 | G16: =G15 -> 45660 | H16: =H15 -> 45696 | I16: MDAJB250102D0049 | J16: QLD-Brisbane | K16: Polyaire | L16: Y | M16: 12月6日开会推后到1月出货
A17: 2024.10.31 | B17: PINBRI20241101024 | C17: MFAB-35WC | D17: 20 | G17: =G16 -> 45660 | H17: =H16 -> 45696 | I17: MDAJB250102D0049 | J17: QLD-Brisbane | K17: Polyaire | L17: Y | M17: RAC CIF,POL-Beijiao, USD 2000
A18: 2024.10.31 | B18: PINBRI20241101024 | C18: MFAB-50NC | D18: 20 | G18: =G17 -> 45660 | H18: =H17 -> 45696 | I18: MDAJB250102D0049 | J18: QLD-Brisbane | K18: Polyaire | L18: Y
A19: 2024.10.31 | B19: PINBRI20241101024 | C19: MFAB-50WC | D19: 20 | G19: =G18 -> 45660 | H19: =H18 -> 45696 | I19: MDAJB250102D0049 | J19: QLD-Brisbane | K19: Polyaire | L19: Y
A20: 2024.10.31 | B20: PINBRI20241101024 | C20: MFAB-71NC | D20: 28 | G20: =G19 -> 45660 | H20: =H19 -> 45696 | I20: MDAJB250102D0049 | J20: QLD-Brisbane | K20: Polyaire | L20: Y
A21: 2024.10.31 | B21: PINBRI20241101024 | C21: MFAB-71WC | D21: 28 | G21: =G20 -> 45660 | H21: =H20 -> 45696 | I21: MDAJB250102D0049 | J21: QLD-Brisbane | K21: Polyaire | L21: Y
A22: 2024.10.31 | B22: PINBRI20241101024 | C22: DUCMI105IHB | D22: 12 | G22: =G21 -> 45660 | H22: =H21 -> 45696 | I22: MDAJB250102D0049 | J22: QLD-Brisbane | K22: Polyaire | L22: Y
A23: 2024.10.31 | B23: PINBRI20241101024 | C23: UCMI105OB | D23: 12 | G23: =G22 -> 45660 | H23: =H22 -> 45696 | I23: MDAJB250102D0049 | J23: QLD-Brisbane | K23: Polyaire | L23: Y
A24: 2024.10.31 | B24: PINBRI20241101024 | C24: DUCMI125IHB | D24: 6 | G24: =G23 -> 45660 | H24: =H23 -> 45696 | I24: MDAJB250102D0049 | J24: QLD-Brisbane | K24: Polyaire | L24: Y
A25: 2024.10.31 | B25: PINBRI20241101024 | C25: UCMI125OB | D25: 6 | G25: =G24 -> 45660 | H25: =H24 -> 45696 | I25: MDAJB250102D0049 | J25: QLD-Brisbane | K25: Polyaire | L25: Y
A26: 2024.10.31 | B26: PINBRI20241101025 | C26: MFAB-20NC | D26: 35 | E26: RAC-002/ SLPU5000261 | G26: =VLOOKUP(CLEAN(SUBSTITUTE(TRIM(MID(E:E,FIND("/",E:E)+1,LEN(E:E)))," ","")),'Customs Decl. & Local Delivery'!D:I,6,0) -> 45660 | H26: =VLOOKUP(CLEAN(SUBSTITUTE(TRIM(MID(E:E,FIND("/",E:E)+1,LEN(E:E)))," ","")),'Customs Decl. & Local Delivery'!D:J,7,0) -> 45696 | I26: MDAJB250102D0048 | J26: QLD-Brisbane | K26: Polyaire | L26: Y | M26: polyaire PO #34624
A27: 2024.10.31 | B27: PINBRI20241101025 | C27: MFAB-20WC | D27: 35 | G27: =G26 -> 45660 | H27: =H26 -> 45696 | I27: MDAJB250102D0048 | J27: QLD-Brisbane | K27: Polyaire | L27: Y | M27: REQ DATE:2025/1/23
A28: 2024.10.31 | B28: PINBRI20241101025 | C28: MFAB-35NC | D28: 60 | G28: =G27 -> 45660 | H28: =H27 -> 45696 | I28: MDAJB250102D0048 | J28: QLD-Brisbane | K28: Polyaire | L28: Y | M28: 12月6日开会推后到1月出货
A29: 2024.10.31 | B29: PINBRI20241101025 | C29: MFAB-35WC | D29: 60 | G29: =G28 -> 45660 | H29: =H28 -> 45696 | I29: MDAJB250102D0048 | J29: QLD-Brisbane | K29: Polyaire | L29: Y | M29: RAC CIF,POL-Beijiao, USD 2000
A30: 2024.10.31 | B30: PINBRI20241101025 | C30: MFAB-50NC | D30: 15 | G30: =G29 -> 45660 | H30: =H29 -> 45696 | I30: MDAJB250102D0048 | J30: QLD-Brisbane | K30: Polyaire | L30: Y
A31: 2024.10.31 | B31: PINBRI20241101025 | C31: MFAB-50WC | D31: 15 | G31: =G30 -> 45660 | H31: =H30 -> 45696 | I31: MDAJB250102D0048 | J31: QLD-Brisbane | K31: Polyaire | L31: Y
A32: 2024.10.31 | B32: PINBRI20241101025 | C32: MFAB-71NC | D32: 30 | G32: =G31 -> 45660 | H32: =H31 -> 45696 | I32: MDAJB250102D0048 | J32: QLD-Brisbane | K32: Polyaire | L32: Y
A33: 2024.10.31 | B33: PINBRI20241101025 | C33: MFAB-71WC | D33: 30 | G33: =G32 -> 45660 | H33: =H32 -> 45696 | I33: MDAJB250102D0048 | J33: QLD-Brisbane | K33: Polyaire | L33: Y
A34: 2024.10.31 | B34: PINBRI20241101025 | C34: MFAB-81NC | D34: 5 | G34: =G33 -> 45660 | H34: =H33 -> 45696 | I34: MDAJB250102D0048 | J34: QLD-Brisbane | K34: Polyaire | L34: Y
A35: 2024.10.31 | B35: PINBRI20241101025 | C35: MFAB-81WC | D35: 5 | G35: =G34 -> 45660 | H35: =H34 -> 45696 | I35: MDAJB250102D0048 | J35: QLD-Brisbane | K35: Polyaire | L35: Y
A36: 2024.10.31 | B36: PINBRI20241101025 | C36: DUCMI105IHB | D36: 4 | G36: =G35 -> 45660 | H36: =H35 -> 45696 | I36: MDAJB250102D0048 | J36: QLD-Brisbane | K36: Polyaire | L36: Y
A37: 2024.10.31 | B37: PINBRI20241101025 | C37: UCMI105OB | D37: 4 | G37: =G36 -> 45660 | H37: =H36 -> 45696 | I37: MDAJB250102D0048 | J37: QLD-Brisbane | K37: Polyaire | L37: Y
A38: 2024.10.31 | B38: PINBRI20241101025 | C38: DUCMI125IHB | D38: 5 | G38: =G37 -> 45660 | H38: =H37 -> 45696 | I38: MDAJB250102D0048 | J38: QLD-Brisbane | K38: Polyaire | L38: Y
A39: 2024.10.31 | B39: PINBRI20241101025 | C39: UCMI125OB | D39: 5 | G39: =G38 -> 45660 | H39: =H38 -> 45696 | I39: MDAJB250102D0048 | J39: QLD-Brisbane | K39: Polyaire | L39: Y
A40: 2024.10.31 | B40: PINBRI20241101025 | C40: DUCMI170IHB | D40: 1 | G40: =G39 -> 45660 | H40: =H39 -> 45696 | I40: MDAJB250102D0048 | J40: QLD-Brisbane | K40: Polyaire | L40: Y
...

Sheet 2025 MBT
A1: 日期 | B1: PI | C1: 型号 | D1: 数量 | E1: Contr # | F1: 客户Req date/需求ETD | G1: ETD | H1: ETA | I1: 发票号 | J1: Destination | K1: Customer | L1: 清关资料 | M1: Remark
A2: 2024.11.27 | B2: PI-MDA-20241127 | C2: MDV-V200WN1 (AU) | D2: 54 | E2: MBT-011/ BHCU4975791 | G2: =VLOOKUP(CLEAN(SUBSTITUTE(TRIM(MID(E:E,FIND("/",E:E)+1,LEN(E:E)))," ","")),'Customs Decl. & Local Delivery'!D:I,6,0) -> 45660 | H2: =VLOOKUP(CLEAN(SUBSTITUTE(TRIM(MID(E:E,FIND("/",E:E)+1,LEN(E:E)))," ","")),'Customs Decl. & Local Delivery'!D:J,7,0) -> 45687 | I2: MDCAS2501030020 | J2: VIC-Mel | K2: No | L2: Y | M2: MBT CIF CNY 18500，POL-BEIJIAO
A3: 2024.11.27 | B3: PI-MDA-20241127 | C3: MIH36GHN18 | D3: 72 | G3: =G2 -> 45660 | H3: =H2 -> 45687 | I3: MDCAS2501030020 | J3: VIC-Mel | K3: No | L3: Y | M3: RM23A遥控器+水泵+左右摆风+wifi内置
A4: 2024.11.27 | B4: PI-MDA-20241127 | C4: MIH45GHN18 | D4: 48 | G4: =G3 -> 45660 | H4: =H3 -> 45687 | I4: MDCAS2501030020 | J4: VIC-Mel | K4: No | L4: Y | M4: RM23A遥控器+水泵+左右摆风+wifi内置
A5: 2024.11.27 | B5: PI-MDA-20241127 | C5: MIH71GHN18 | D5: 60 | G5: =G4 -> 45660 | H5: =H4 -> 45687 | I5: MDCAS2501030020 | J5: VIC-Mel | K5: No | L5: Y | M5: RM23A遥控器+水泵+左右摆风+wifi内置
A6: 2024.11.27 | B6: PI-MDA-20241127 | C6: EEV线 | D6: 100 | G6: =G5 -> 45660 | H6: =H5 -> 45687 | I6: MDCAS2501030020 | J6: VIC-Mel | K6: No | L6: Y
A7: 2024.11.27 | B7: PI-MDA-20241127 | C7: MDV-V200WN1 (AU) | D7: 54 | E7: MBT-012/ BSIU9877805 | G7: =VLOOKUP(CLEAN(SUBSTITUTE(TRIM(MID(E:E,FIND("/",E:E)+1,LEN(E:E)))," ","")),'Customs Decl. & Local Delivery'!D:I,6,0) -> 45660 | H7: =VLOOKUP(CLEAN(SUBSTITUTE(TRIM(MID(E:E,FIND("/",E:E)+1,LEN(E:E)))," ","")),'Customs Decl. & Local Delivery'!D:J,7,0) -> 45687 | I7: MDCAS2501030020 | J7: VIC-Mel | K7: No | L7: Y | M7: MBT CIF CNY 18500，POL-BEIJIAO
A8: 2024.11.27 | B8: PI-MDA-20241127 | C8: MIH36GHN18 | D8: 12 | G8: =G7 -> 45660 | H8: =H7 -> 45687 | I8: MDCAS2501030020 | J8: VIC-Mel | K8: No | L8: Y | M8: RM23A遥控器+水泵+左右摆风+wifi内置
A9: 2024.11.27 | B9: PI-MDA-20241127 | C9: MIH45GHN18 | D9: 8 | G9: =G8 -> 45660 | H9: =H8 -> 45687 | I9: MDCAS2501030020 | J9: VIC-Mel | K9: No | L9: Y | M9: RM23A遥控器+水泵+左右摆风+wifi内置
A10: 2024.11.27 | B10: PI-MDA-20241127 | C10: MIH71GHN18 | D10: 10 | G10: =G9 -> 45660 | H10: =H9 -> 45687 | I10: MDCAS2501030020 | J10: VIC-Mel | K10: No | L10: Y | M10: RM23A遥控器+水泵+左右摆风+wifi内置
A11: 2024.11.27 | B11: PI-MDA-20241127 | C11: MIH36GHN18 | D11: 60 | G11: =G10 -> 45660 | H11: =H10 -> 45687 | I11: MDCAS2501030020 | J11: VIC-Mel | K11: No | L11: Y | M11: RM23A遥控器+水泵+左右摆风+wifi内置
A12: 2024.11.27 | B12: PI-MDA-20241127 | C12: MIH45GHN18 | D12: 40 | G12: =G11 -> 45660 | H12: =H11 -> 45687 | I12: MDCAS2501030020 | J12: VIC-Mel | K12: No | L12: Y | M12: RM23A遥控器+水泵+左右摆风+wifi内置
A13: 2024.11.27 | B13: PI-MDA-20241127 | C13: MIH71GHN18 | D13: 50 | G13: =G12 -> 45660 | H13: =H12 -> 45687 | I13: MDCAS2501030020 | J13: VIC-Mel | K13: No | L13: Y | M13: RM23A遥控器+水泵+左右摆风+wifi内置
A14: 2024.11.27 | B14: PI-MDA-20241127 | C14: RM23A遥控器 | D14: 100 | G14: =G13 -> 45660 | H14: =H13 -> 45687 | I14: MDCAS2501030020 | J14: VIC-Mel | K14: No | L14: Y
A15: 2024.11.27 | B15: PI-MDA-20241127 | C15: MDV-V200WN1 (AU) | D15: 54 | E15: MBT-013/ BSIU9886643 | G15: =VLOOKUP(CLEAN(SUBSTITUTE(TRIM(MID(E:E,FIND("/",E:E)+1,LEN(E:E)))," ","")),'Customs Decl. & Local Delivery'!D:I,6,0) -> 45660 | H15: =VLOOKUP(CLEAN(SUBSTITUTE(TRIM(MID(E:E,FIND("/",E:E)+1,LEN(E:E)))," ","")),'Customs Decl. & Local Delivery'!D:J,7,0) -> 45687 | I15: MDCAS2501030020 | J15: VIC-Mel | K15: No | L15: Y | M15: MBT CIF CNY 18500，POL-BEIJIAO
A16: 2024.11.27 | B16: PI-MDA-20241127 | C16: MIH36GHN18 | D16: 72 | G16: =G15 -> 45660 | H16: =H15 -> 45687 | I16: MDCAS2501030020 | J16: VIC-Mel | K16: No | L16: Y | M16: RM23A遥控器+水泵+左右摆风+wifi内置
A17: 2024.11.27 | B17: PI-MDA-20241127 | C17: MIH45GHN18 | D17: 48 | G17: =G16 -> 45660 | H17: =H16 -> 45687 | I17: MDCAS2501030020 | J17: VIC-Mel | K17: No | L17: Y | M17: RM23A遥控器+水泵+左右摆风+wifi内置
A18: 2024.11.27 | B18: PI-MDA-20241127 | C18: MIH71GHN18 | D18: 60 | G18: =G17 -> 45660 | H18: =H17 -> 45687 | I18: MDCAS2501030020 | J18: VIC-Mel | K18: No | L18: Y | M18: RM23A遥控器+水泵+左右摆风+wifi内置
A19: 2024.11.27 | B19: PI-MDA-20241127 | C19: MDV-V200WN1 (AU) | D19: 54 | E19: MBT-014/ FCIU7307262 | G19: =VLOOKUP(CLEAN(SUBSTITUTE(TRIM(MID(E:E,FIND("/",E:E)+1,LEN(E:E)))," ","")),'Customs Decl. & Local Delivery'!D:I,6,0) -> 45660 | H19: =VLOOKUP(CLEAN(SUBSTITUTE(TRIM(MID(E:E,FIND("/",E:E)+1,LEN(E:E)))," ","")),'Customs Decl. & Local Delivery'!D:J,7,0) -> 45687 | I19: MDCAS2501030020 | J19: VIC-Mel | K19: No | L19: Y | M19: MBT CIF CNY 18500，POL-BEIJIAO
A20: 2024.11.27 | B20: PI-MDA-20241127 | C20: MIH36GHN18 | D20: 72 | G20: =G19 -> 45660 | H20: =H19 -> 45687 | I20: MDCAS2501030020 | J20: VIC-Mel | K20: No | L20: Y | M20: RM23A遥控器+水泵+左右摆风+wifi内置
A21: 2024.11.27 | B21: PI-MDA-20241127 | C21: MIH45GHN18 | D21: 48 | G21: =G20 -> 45660 | H21: =H20 -> 45687 | I21: MDCAS2501030020 | J21: VIC-Mel | K21: No | L21: Y | M21: RM23A遥控器+水泵+左右摆风+wifi内置
A22: 2024.11.27 | B22: PI-MDA-20241127 | C22: MIH71GHN18 | D22: 60 | G22: =G21 -> 45660 | H22: =H21 -> 45687 | I22: MDCAS2501030020 | J22: VIC-Mel | K22: No | L22: Y | M22: RM23A遥控器+水泵+左右摆风+wifi内置
A23: 2024.11.27 | B23: PI-MDA-20241127 | C23: MDV-V200WN1 (AU) | D23: 54 | E23: MBT-015/ FDCU0006143 | G23: =VLOOKUP(CLEAN(SUBSTITUTE(TRIM(MID(E:E,FIND("/",E:E)+1,LEN(E:E)))," ","")),'Customs Decl. & Local Delivery'!D:I,6,0) -> 45660 | H23: =VLOOKUP(CLEAN(SUBSTITUTE(TRIM(MID(E:E,FIND("/",E:E)+1,LEN(E:E)))," ","")),'Customs Decl. & Local Delivery'!D:J,7,0) -> 45687 | I23: MDCAS2501030020 | J23: VIC-Mel | K23: Odisee | L23: Y | M23: MBT CIF CNY 18500，POL-BEIJIAO
A24: 2024.11.27 | B24: PI-MDA-20241127 | C24: MIH36GHN18 | D24: 72 | G24: =G23 -> 45660 | H24: =H23 -> 45687 | I24: MDCAS2501030020 | J24: VIC-Mel | K24: Odisee | L24: Y | M24: RM23A遥控器+水泵+左右摆风+wifi内置
A25: 2024.11.27 | B25: PI-MDA-20241127 | C25: MIH45GHN18 | D25: 48 | G25: =G24 -> 45660 | H25: =H24 -> 45687 | I25: MDCAS2501030020 | J25: VIC-Mel | K25: Odisee | L25: Y | M25: RM23A遥控器+水泵+左右摆风+wifi内置
A26: 2024.11.27 | B26: PI-MDA-20241127 | C26: MIH71GHN18 | D26: 60 | G26: =G25 -> 45660 | H26: =H25 -> 45687 | I26: MDCAS2501030020 | J26: VIC-Mel | K26: Odisee | L26: Y | M26: RM23A遥控器+水泵+左右摆风+wifi内置
A27: 2024.11.27 | B27: PI-MDA-20241127 | C27: MDV-V200WN1 (AU) | D27: 54 | E27: MBT-006/ FFAU4399308 | G27: =VLOOKUP(CLEAN(SUBSTITUTE(TRIM(MID(E:E,FIND("/",E:E)+1,LEN(E:E)))," ","")),'Customs Decl. & Local Delivery'!D:I,6,0) -> 45667 | H27: =VLOOKUP(CLEAN(SUBSTITUTE(TRIM(MID(E:E,FIND("/",E:E)+1,LEN(E:E)))," ","")),'Customs Decl. & Local Delivery'!D:J,7,0) -> 45685 | I27: MDCAS2501010082 | J27: VIC-Mel | K27: Odisee | L27: Y | M27: MBT CIF CNY 18500，POL-BEIJIAO
A28: 2024.11.27 | B28: PI-MDA-20241127 | C28: MIH36GHN18 | D28: 45 | G28: =G27 -> 45667 | H28: =H27 -> 45685 | I28: MDCAS2501010082 | J28: VIC-Mel | K28: Odisee | L28: Y | M28: RM23A遥控器+水泵+左右摆风+wifi内置
A29: 2024.11.27 | B29: PI-MDA-20241127 | C29: MIH45GHN18 | D29: 30 | G29: =G28 -> 45667 | H29: =H28 -> 45685 | I29: MDCAS2501010082 | J29: VIC-Mel | K29: Odisee | L29: Y | M29: RM23A遥控器+水泵+左右摆风+wifi内置
A30: 2024.11.27 | B30: PI-MDA-20241127 | C30: MIH71GHN18 | D30: 38 | G30: =G29 -> 45667 | H30: =H29 -> 45685 | I30: MDCAS2501010082 | J30: VIC-Mel | K30: Odisee | L30: Y | M30: RM23A遥控器+水泵+左右摆风+wifi内置
A31: 2024.11.27 | B31: PI-MDA-20241127 | C31: MIH80GHN18 | D31: 53 | G31: =G30 -> 45667 | H31: =H30 -> 45685 | I31: MDCAS2501010082 | J31: VIC-Mel | K31: Odisee | L31: Y | M31: RM23A遥控器+水泵+左右摆风+wifi内置
A32: 2024.11.27 | B32: PI-MDA-20241127 | C32: MDV-V200WN1 (AU) | D32: 54 | E32: MBT-007/ SEKU5869860 | G32: =VLOOKUP(CLEAN(SUBSTITUTE(TRIM(MID(E:E,FIND("/",E:E)+1,LEN(E:E)))," ","")),'Customs Decl. & Local Delivery'!D:I,6,0) -> 45667 | H32: =VLOOKUP(CLEAN(SUBSTITUTE(TRIM(MID(E:E,FIND("/",E:E)+1,LEN(E:E)))," ","")),'Customs Decl. & Local Delivery'!D:J,7,0) -> 45685 | I32: MDCAS2501010082 | J32: VIC-Mel | K32: Odisee | L32: Y | M32: MBT CIF CNY 18500，POL-BEIJIAO
A33: 2024.11.27 | B33: PI-MDA-20241127 | C33: MIH36GHN18 | D33: 45 | G33: =G32 -> 45667 | H33: =H32 -> 45685 | I33: MDCAS2501010082 | J33: VIC-Mel | K33: Odisee | L33: Y | M33: RM23A遥控器+水泵+左右摆风+wifi内置
A34: 2024.11.27 | B34: PI-MDA-20241127 | C34: MIH45GHN18 | D34: 30 | G34: =G33 -> 45667 | H34: =H33 -> 45685 | I34: MDCAS2501010082 | J34: VIC-Mel | K34: Odisee | L34: Y | M34: RM23A遥控器+水泵+左右摆风+wifi内置
A35: 2024.11.27 | B35: PI-MDA-20241127 | C35: MIH71GHN18 | D35: 38 | G35: =G34 -> 45667 | H35: =H34 -> 45685 | I35: MDCAS2501010082 | J35: VIC-Mel | K35: Odisee | L35: Y | M35: RM23A遥控器+水泵+左右摆风+wifi内置
A36: 2024.11.27 | B36: PI-MDA-20241127 | C36: MIH80GHN18 | D36: 53 | G36: =G35 -> 45667 | H36: =H35 -> 45685 | I36: MDCAS2501010082 | J36: VIC-Mel | K36: Odisee | L36: Y | M36: RM23A遥控器+水泵+左右摆风+wifi内置
A37: 2024.11.27 | B37: PI-MDA-20241127 | C37: MDV-V200WN1 (AU) | D37: 54 | E37: MBT-008/ TLLU7977152 | G37: =VLOOKUP(CLEAN(SUBSTITUTE(TRIM(MID(E:E,FIND("/",E:E)+1,LEN(E:E)))," ","")),'Customs Decl. & Local Delivery'!D:I,6,0) -> 45667 | H37: =VLOOKUP(CLEAN(SUBSTITUTE(TRIM(MID(E:E,FIND("/",E:E)+1,LEN(E:E)))," ","")),'Customs Decl. & Local Delivery'!D:J,7,0) -> 45685 | I37: MDCAS2501010082 | J37: VIC-Mel | K37: No | L37: Y | M37: MBT CIF CNY 18500，POL-BEIJIAO
A38: 2024.11.27 | B38: PI-MDA-20241127 | C38: MIH36GHN18 | D38: 45 | G38: =G37 -> 45667 | H38: =H37 -> 45685 | I38: MDCAS2501010082 | J38: VIC-Mel | K38: No | L38: Y | M38: RM23A遥控器+水泵+左右摆风+wifi内置
A39: 2024.11.27 | B39: PI-MDA-20241127 | C39: MIH45GHN18 | D39: 30 | G39: =G38 -> 45667 | H39: =H38 -> 45685 | I39: MDCAS2501010082 | J39: VIC-Mel | K39: No | L39: Y | M39: RM23A遥控器+水泵+左右摆风+wifi内置
A40: 2024.11.27 | B40: PI-MDA-20241127 | C40: MIH71GHN18 | D40: 38 | G40: =G39 -> 45667 | H40: =H39 -> 45685 | I40: MDCAS2501010082 | J40: VIC-Mel | K40: No | L40: Y | M40: RM23A遥控器+水泵+左右摆风+wifi内置
...

Sheet Customs Decl. & Local Delivery
A1: PO Date | B1: Midea Department | C1: BL No | D1: Container # | E1: Sea freight cost | F1: Terms | G1: Shipping Company | H1: Vessel Voy # | I1: ETD | J1: ETA | K1: Destination | L1: Warehouse address | M1: PO# | N1: 清关 | O1: GST | P1: 卸柜费用(AUD) | Q1: CCL Docs | R1: tax invoice send | S1: tax payment | T1: EDO send | U1: Delivery Date | V1: 还柜Y/N | W1: LFD | X1: Remark
A2: 2023.9.12 | C2: ZIMUIAU3028180 | D2: ZCSU7532999 | G2: ZIM | H2: SUI SHUN FENG JI 968 231225 | I2: 45285 | J2: 45306 | K2: QLD-Brisbane | L2: Unit 2 60 Dulacca Street Acacia Ridge QLD 4110 | M2: Polyaire 12439 | Q2: 45299 | U2: 45313 | V2: Y | W2: =J2+14 -> 45320 | X2: 6sets of Training Rack Wrongly Loaded in by RAC
A3: 2023.11.20 | C3: 712310681045 | D3: TSSU5163181 | G3: TSL | H3: TS VANCOUVER/2306S | I3: 45290 | J3: 45307 | K3: NSW-Sydney | L3: Syd Warehouse | M3: - | Q3: 45297 | U3: 45313 | V3: Y | W3: =J3+14 -> 45321
A4: 2023.9.22 | C4: ZIMUIAU3028182 | D4: ZCSU6984356 | G4: ZIM | H4: SUI SHUN FENG JI 968 231225 | I4: 45285 | J4: 45310 | K4: Vic-Mel | L4: Mel Warehouse | M4: - | Q4: 45289 | U4: 45320 | V4: Y | W4: =J4+14 -> 45324
A5: 2023.11.20 | C5: ZIMUGZH0351951 | D5: ZCSU7632581 | G5: ZIM | H5: ZIM GANGES 1/S | I5: 45292 | J5: 45310 | K5: VIC-Mel | L5: Mel Warehouse | M5: - | Q5: 45297 | U5: 45320 | V5: Y | W5: =J5+14 -> 45324
A6: 2023.11.20 | C6: ZIMUGZH0351952 | D6: ZCSU6797458 | G6: ZIM | H6: ZIM GANGES 1/S | I6: 45292 | J6: 45310 | K6: VIC-Mel | L6: Mel Warehouse | M6: - | Q6: 45297 | U6: 45320 | V6: Y | W6: =J6+14 -> 45324
A7: 2023.10.10 | C7: ZIMUIAU3028181 | D7: ZCSU6604292 | G7: ZIM | H7: SHUN YI 818/231226 | I7: 45285 | J7: 45310 | K7: VIC-Mel | L7: Mel Warehouse | M7: - | Q7: 45299 | U7: 45320 | V7: Y | W7: =J7+14 -> 45324
A8: 2023.12.8 | C8: ZIMUGZH0353919 | D8: ZCSU7049105 | G8: ZIM | H8: ZIM GANGES 1/S | I8: 45297 | J8: 45310 | K8: VIC-Mel | L8: Mel Warehouse | M8: - | Q8: 45303 | U8: 45321 | V8: Y | W8: =J8+14 -> 45324
A9: 2023.11.20 | C9: ZIMUGZH0351956 | D9: ZCSU7232970 | G9: ZIM | H9: ZIM GANGES 1/S | I9: 45291 | J9: 45310 | K9: VIC-Mel | L9: Mel Warehouse | M9: - | Q9: 45303 | U9: 45320 | V9: Y | W9: =J9+14 -> 45324
A10: 2023.11.20 | C10: 712310678380 | D10: FFAU4387082 | G10: TSL | H10: TS VANCOUVER/2306S | I10: 45290 | J10: 45312 | K10: VIC-Mel | L10: Mel Warehouse | M10: - | Q10: 45296 | U10: 45316 | V10: Y | W10: =J10+14 -> 45326
A11: 2023.10.17 | C11: ZIMUIAU3028183 | D11: UETU5272451 | G11: ZIM | H11: GAO LAN 813/231226 | I11: 45285 | J11: 45320 | K11: NSW-Sydney | L11: 71/NSW - 71 Padstow 50 GIBSON AVENUE Padstow NSW 2211 changed to 6 Avalli Road, Prestons, NSW 2170 | M11: Polyaire 14578 | Q11: 45295 | U11: 45327 | V11: Y | W11: =J11+14 -> 45334 | X11: delayed ETA from 1/19 to 1/29
A12: 2023.10.20 | C12: COSU8045938370 | D12: OOLU6882120 | G12: COSCO | H12: JIN RONG 02 / 078S | I12: 45280 | J12: 45335 | K12: WA-Frementle | L12: 61 Conquest Way, Wangara WA 6065 | M12: Polyaire 14809 | Q12: 45289 | U12: 45337 | V12: Y | W12: =J12+17 -> 45352 | X12: 2pcs of UCMI105OB for aftersales units, Delivery rejected by Polyaire due to Maersk didn't deliver after approval provided
A13: 2024.2.3 | C13: SZCK30090100 | D13: PCIU8558072 | G13: PIL | H13: TS HOCHIMINH 2308S | I13: 45322 | J13: 45337 | K13: VIC-Mel | L13: Mel Warehouse | M13: - | Q13: 45325 | U13: 45343 | V13: Y | W13: =J13+14 -> 45351
A14: 2023.12.8 | C14: OOLU2731653561 | D14: OOCU7951147 | G14: OOCL | H14: CMA CGM MONTMARTRE 0FMEXW1MA | I14: 45329 | J14: 45353 | K14: WA-Frementle | L14: 61 Conquest Way, Wangara WA 6065 | M14: Polyaire 17927 | Q14: 45344 | U14: 45358 | V14: Y | W14: =J14+14 -> 45367
A15: 2023.11.6 | C15: COSU8045938400 | D15: FSCU8884988 | G15: COSCO | H15: JIN LONG 689 329S | I15: 45282 | J15: 45355 | K15: SA-Adelaide | L15: 11-13 White Road, Gepps Cross SA 5094 | M15: Polyaire 10285 | Q15: 45287 | U15: 45359 | V15: Y | W15: =J15+14 -> 45369
A16: 2023.11.15 | C16: COSU8045938401 | D16: OOLU9349794 | G16: COSCO | H16: JIN RONG 02 / 078S | I16: 45282 | J16: 45355 | K16: SA-Adelaide | L16: 11-13 White Road, Gepps Cross SA 5094 | M16: Polyaire 16392 | Q16: 45287 | U16: 45358 | V16: Y | W16: =J16+14 -> 45369
A17: 2023.11.23 | C17: 712410076277 | D17: TSSU5110052 | G17: TSL | H17: TS SHEKOU 2401S | I17: 45350 | J17: 45365 | K17: QLD-Brisbane | L17: QLD Warehouse | M17: SAI ORD00000178 | Q17: 45356 | U17: 45371 | V17: Y | W17: =J17+21 -> 45386
A18: 2024.1.4 | C18: 712410074419 | D18: TRHU8701813 | G18: TSL | H18: TS SHEKOU 2401S | I18: 45350 | J18: 45372 | K18: Vic-Mel | L18: Mel Warehouse | M18: Odisee PO0051 | Q18: 45352 | U18: 45376 | V18: Y | W18: =J18+21 -> 45393
A19: 2024.1.9 | C19: 712410074464 | D19: TRHU8015855 | G19: TSL | H19: TS SHEKOU 2401S | I19: 45350 | J19: 45372 | K19: Vic-Mel | L19: Saving Earth | M19: Odisee PO0069 | Q19: 45352 | U19: 45374 | V19: Y | W19: =J19+21 -> 45393
A20: 2023.11.23 | C20: 712410083831 | D20: TSSU5000733 | G20: TSL | H20: TS SHEKOU 2401S | I20: 45350 | J20: 45372 | K20: Vic-Mel | L20: Mel Warehouse | M20: Part for Odisee Short-loaded | Q20: 45358 | U20: 45376 | V20: Y | W20: =J20+21 -> 45393
A21: 2024.1.17 | C21: COSU6378228180 | D21: OOLU9706150 | G21: COSCO | H21: COSCO HONG KONG 184S | I21: 45356 | J21: 45372 | K21: VIC-Mel | L21: Mel Warehouse | M21: - | Q21: 45367 | U21: 45374 | V21: Y | W21: =J21+21 -> 45393
A22: 2024.1.17 | C22: COSU6378228180 | D22: TGHU6924225 | G22: COSCO | H22: COSCO HONG KONG 184S | I22: 45356 | J22: 45372 | K22: VIC-Mel | L22: Mel Warehouse | M22: - | Q22: 45367 | U22: 45375 | V22: Y | W22: =J22+21 -> 45393
A23: 2024.1.17 | C23: COSU6378228180 | D23: CAAU6128066 | G23: COSCO | H23: COSCO HONG KONG 184S | I23: 45356 | J23: 45372 | K23: VIC-Mel | L23: Mel Warehouse | M23: Odisee PO0070 | Q23: 45367 | U23: 45374 | V23: Y | W23: =J23+21 -> 45393
A24: 2024.1.17 | C24: COSU6378228180 | D24: CSNU6622758 | G24: COSCO | H24: COSCO HONG KONG 184S | I24: 45356 | J24: 45372 | K24: VIC-Mel | L24: Mel Warehouse | M24: - | Q24: 45367 | U24: 45376 | V24: Y | W24: =J24+21 -> 45393
A25: 2024.1.9 | C25: 712410076406 | D25: TSSU5079194 | G25: TSL | H25: TS SHEKOU 2401S | I25: 45350 | J25: 45372 | K25: Vic-Mel | L25: Saving Earth | M25: Odisee PO0070 | Q25: 45352 | U25: 45376 | V25: Y | W25: =J25+21 -> 45393
A26: 2024.1.12 | C26: 712410102792 | D26: TEMU7935496 | G26: TSL | H26: KOTA LIMA 0015S | I26: 45357 | J26: 45376 | K26: Vic-Mel | L26: Mel Warehouse | M26: - | Q26: 45363 | U26: 45383 | V26: Y | W26: =J26+21 -> 45397
A27: 2024.1.12 | C27: 712410102815 | D27: TSSU5087374 | G27: TSL | H27: KOTA LIMA 0015S | I27: 45357 | J27: 45376 | K27: VIC-Mel | L27: Mel Warehouse | M27: - | Q27: 45362 | U27: 45381 | V27: Y | W27: =J27+21 -> 45397
A28: 2024.1.17 | C28: OOLU2146640990 | D28: OOCU8176764 | G28: OOCL | H28: COSCO HONG KONG / 184S | I28: 45356 | J28: 45377 | K28: QLD-Brisbane | L28: QLD Warehouse | M28: - | Q28: 45362 | U28: 45379 | V28: Y | W28: =J28+21 -> 45398
... A48: 2024.2.17 | C48: 712410155217 | D48: TIIU4454937 | G48: TSL | H48: KOTA MAKMUR 0318S | I48: 45382 | J48: 45402 | K48: VIC-Mel | L48: Mel Warehouse | M48: - | Q48: 45387 | U48: 45403 | V48: Y | W48: =J48+21 -> 45423
A49: 2024.2.17 | C49: ZIMUGZH0379364 | D49: ZCSU7140220 | G49: ZIM | H49: MARIANNA I/8/S | I49: 45390 | J49: 45406 | K49: VIC-Mel | L49: Mel Warehouse | M49: - | Q49: 45400 | U49: 45411 | V49: Y | W49: =J49+14 -> 45420
A50: 2024.2.23 | C50: 712410174652 | D50: TRHU8707447 | G50: TSL | H50: NORTHERN DISCOVERY 24003S | I50: 45389 | J50: 45407 | K50: VIC-Mel | L50: Mel Warehouse | M50: - | Q50: 45393 | U50: 45412 | V50: Y | W50: =J50+21 -> 45428
A51: 2024.2.22 | C51: 712410176946 | D51: TCNU6590893 | G51: TSL | H51: NORTHERN DISCOVERY 24003S | I51: 45389 | J51: 45407 | K51: VIC-Mel | M51: Odisee PO 0122+Odisee PO0093 | Q51: 45391 | U51: 45412 | V51: Y | W51: =J51+21 -> 45428
A52: 2024.1.30 | C52: HUSP40020500 | D52: PCIU9370500 | G52: PIL | H52: NORTHERN DISCOVERY 24003S | I52: 45389 | J52: 45407 | K52: VIC-Mel | L52: QLD Warehouse | M52: Odisee PO 0123 | Q52: 45391 | U52: 45412 | V52: Y | W52: =J52+14 -> 45421
A53: - | C53: CGZMF240300645 | D53: TLLU3365098 | G53: CTS | H53: NORTHERN DISCOVERY 24003S | I53: 45389 | J53: 45407 | K53: NSW-Sydney | L53: - | M53: ARBS Samples | Q53: 45397 | U53: 45413 | V53: Y | W53: =J53+14 -> 45421
A54: 2024.1.25 | C54: OOLU2147185530 | D54: GCXU5457857 | G54: OOCL | H54: GONG HUA V.240403 | I54: 45385 | J54: 45411 | K54: WA-Frementle | L54: 61 Conquest Way, Wangara WA 6065 | M54: Polyaire PO#: 19841 | Q54: 45393 | U54: 45418 | V54: Y | W54: =J54+14 -> 45425
A55: 2024.2.22 | C55: 712410173112 | D55: TCKU7567466 | G55: TSL | H55: TS CHENNAI 2402S | I55: 45396 | J55: 45411 | K55: VIC-Mel | L55: QLD Warehouse | M55: - | Q55: 45397 | U55: 45415 | V55: Y | W55: =J55+21 -> 45432
A56: 2024.2.22 | C56: 712410176960 | D56: MAGU5620082 | G56: TSL | H56: TS CHENNAI 2402S | I56: 45396 | J56: 45411 | K56: VIC-Mel | L56: QLD Warehouse | M56: - | Q56: 45397 | U56: 45415 | V56: Y | W56: =J56+21 -> 45432
A57: 2024.2.22 | C57: 712410179602 | D57: TEMU7738310 | G57: TSL | H57: TS CHENNAI 2402S | I57: 45396 | J57: 45411 | K57: VIC-Mel | L57: QLD Warehouse | M57: - | Q57: 45397 | U57: 45415 | V57: Y | W57: =J57+21 -> 45432
A58: 2024.2.22 | C58: 712410179626 | D58: TEMU7955390 | G58: TSL | H58: TS CHENNAI 2402S | I58: 45396 | J58: 45411 | K58: VIC-Mel | L58: QLD Warehouse | M58: - | Q58: 45397 | U58: 45415 | V58: Y | W58: =J58+21 -> 45432
A59: 2024.2.22 | C59: ZIMUGZH0380497 | D59: TEMU7418132 | G59: ZIM | H59: DANUBE 5/S | I59: 45396 | J59: 45412 | K59: VIC-Mel | L59: QLD Warehouse | M59: - | O59: 13652.12 | Q59: 45397 | U59: 45418 | V59: Y | W59: =J59+14 -> 45426
...

Sheet SP
A1: PO No. | B1: Ctn No. | C1: Factory Code | D1: Description | E1: QTY | F1: INV. NO | G1: Destination | H1: ETA | I1: Remark
A2: - | B2: TSSU5194515 | C2: 90GP095 | D2: 90GP095 Gas Cooktop | E2: 1 | F2: MDWZB241028D0003 | G2: VIC-Mel | H2: 45617 | I2: KWHA MAZ Sample
C3: 60GJ084 | D3: 60GJ084 Gas Cooktop | E3: 1 | F3: MDWZB241028D0003 | G3: VIC-Mel
C4: 30GB095 | D4: 30GB095 Gas Cooktop | E4: 1 | F4: MDWZB241028D0003 | G4: VIC-Mel
C5: 75GP095 | D5: 75GP095 Gas Cooktop | E5: 1 | F5: MDWZB241028D0003 | G5: VIC-Mel
C6: 60SL403 | D6: 60SL403 Gas Cooktop | E6: 1 | F6: MDWZB241028D0003 | G6: VIC-Mel
C7: 75SP021 | D7: 75SP021 Gas Cooktop | E7: 1 | F7: MDWZB241028D0003 | G7: VIC-Mel
C8: - | D8: DISHWASHER | E8: 1 | F8: MDWZB241028D0003 | G8: VIC-Mel
C9: - | D9: VALVE | E9: 200 | F9: MDWZB241028D0003 | G9: VIC-Mel | I9: FOC，MWPU4W的阀体
A10: KWHA 27_08_24 | B10: TSSU5063562 | C10: 17476000007431 | D10: Heating Tube Assembly | E10: 10 | F10: MDWDB241107D0001 | G10: VIC-Mel | H10: 45630
A11: SR240923023 | C11: 11201007003440 | D11: Room Temperature Sensor | E11: 1 | F11: MDCAS2411070005P | G11: VIC-Mel | I11: MBT Quality Claim-7月
A12: SR240923023 | C12: 17122300007572 | D12: Indoor Unit Main Control Board | E12: 1 | F12: MDCAS2411070005P | G12: VIC-Mel
A13: SR240904009 | C13: 17127000012938 | D13: Outdoor main control board assembly | E13: 2 | F13: MDCAS2411070005P | G13: VIC-Mel
A14: - | C14: 11001010000063 | D14: Induction Pump | E14: 20 | F14: MDAJB241107D0006 | G14: VIC-Mel | I14: RAC Q4支持配件
C15: 11002015003981 | D15: Brushless DC Motor | E15: 8 | F15: MDAJB241107D0006 | G15: VIC-Mel
C16: 11002015009825 | D16: Brushless DC Motor | E16: 26 | F16: MDAJB241107D0006 | G16: VIC-Mel
C17: 11002015008264 | D17: Brushless DC Motor | E17: 10 | F17: MDAJB241107D0006 | G17: VIC-Mel
C18: 11002015003861 | D18: Brushless DC Motor | E18: 10 | F18: MDAJB241107D0006 | G18: VIC-Mel
C19: 11002015000366 | D19: Brushless DC Motor | E19: 20 | F19: MDAJB241107D0006 | G19: VIC-Mel
C20: 11002015018478 | D20: Brushless DC Motor | E20: 5 | F20: MDAJB241107D0006 | G20: VIC-Mel
C21: 11002015002521 | D21: Brushless DC Motor | E21: 10 | F21: MDAJB241107D0006 | G21: VIC-Mel
C22: 11002015000187 | D22: Brushless DC Motor | E22: 4 | F22: MDAJB241107D0006 | G22: VIC-Mel
C23: 11002010000143 | D23: Stepper Motor | E23: 30 | F23: MDAJB241107D0006 | G23: VIC-Mel
C24: 11002015000051 | D24: Brushless DC Motor | E24: 15 | F24: MDAJB241107D0006 | G24: VIC-Mel
C25: 11002015000150 | D25: Brushless DC Motor | E25: 15 | F25: MDAJB241107D0006 | G25: VIC-Mel
C26: 11002015000247 | D26: Brushless DC Motor | E26: 7 | F26: MDAJB241107D0006 | G26: VIC-Mel
... C87: 17401204017449 | D87: LV Junction Cable Subassembly | E87: 40 | F87: MDAJB241107D0006 | G87: VIC-Mel
A88: - | B88: BSIU9814155 | C88: 17122000A18354 | D88: Outdoor main control board subassembly | E88: 5 | F88: MDAJB241126D0010 | G88: VIC-Mel | H88: 45648 | I88: RAC 售后支持配件，FOC
A89: RAC_01_11_24 | C89: 12122000025627 | D89: Panel Frame Assembly | E89: 1 | F89: MDAJB241126D0009 | G89: VIC-Mel
A90: MBT_09_12_24 | B90: GAOU6740052 | C90: 17122300003794 | D90: Outdoor Main Control Board Assembly | E90: 1 | F90: MDCAS250103001200001 | G90: QLD-Brisbane | H90: 45678 | I90: 售后-Compact PO 00000314
A91: - | B91: TSSU5116615 | C91: 12566200A19238 | D91: Glass Panel Assembly | E91: 3 | F91: MDWZB250118D0005 | G91: VIC-Mel | H91: 45708 | I91: KWHA 售后FOC配件
A92: KWHA_13_12_24 | C92: 15663200A09024 | D92: Water purifier filter MWPU1W | E92: 12 | F92: MDWJB250117D0006 | G92: VIC-Mel
A93: PINBRI20241210002 | C93: - | D93: MFAG80VA-W | E93: 1 | F93: MDAJB250117D0014 | G93: VIC-Mel | I93: Aftersales. RAC铭牌
A94: PINBRI20241210002 | C94: - | D94: MFAG20VA-N | E94: 30 | F94: MDAJB250117D0014
A95: PINBRI20241210002 | C95: - | D95: MFAG20VA-W | E95: 30 | F95: MDAJB250117D0014
A96: PINBRI20241210002 | C96: - | D96: MFAG60VA-N | E96: 40 | F96: MDAJB250117D0014
A97: PINBRI20241210002 | C97: - | D97: MFAG60VA-W | E97: 40 | F97: MDAJB250117D0014
A98: PINBRI20241210002 | C98: - | D98: MFAG51VA-N | E98: 15 | F98: MDAJB250117D0014
A99: PINBRI20241210002 | C99: - | D99: MFAG51VA-W | E99: 15 | F99: MDAJB250117D0014
A100: PINBRI20241210002 | C100: - | D100: MFAB90NB | E100: 2 | F100: MDAJB250117D0014
...

Sheet 物料
A1: Ctn No. | B1: Description | C1: QTY | D1: INV. NO | E1: Destination | F1: Department | G1: ETA | H1: Remark
A2: TCKU7956323 | B2: 冰箱样品 | C2: 1 | D2: - | E2: VIC-Mel | F2: Sales | G2: 45617 | H2: NCE公司
A3: TSSU5063562 | B3: MFAG35VA-N Indoor unit | C3: 2 | D3: MDAJB241107D0005 | E3: VIC-Mel | F3: Marketing | G3: 45630 | H3: RAC道具
B4: MFAG35VA-X3 Outdoor unit | C4: 4 | D4: MDAJB241107D0005 | E4: VIC-Mel | F4: Marketing
B5: Promotional material 无 屏幕演示道具 无 | C5: 3 | D5: MDAJB241107D0005 | E5: VIC-Mel | F5: Marketing
B6: Promotional material 无 石墨烯中型道具 无 | C6: 3 | D6: MDAJB241107D0005 | E6: VIC-Mel | F6: Marketing
B7: Promotional material 无 AEP-2400H 无 | C7: 1 | D7: MDAJB241107D0005 | E7: VIC-Mel | F7: Marketing | H7: RAC展架
B8: Promotional material 无 AEP-2400H 无 | C8: 1 | D8: MDAJB241107D0005 | E8: VIC-Mel | F8: Marketing
B9: Promotional material 无 WG+分体+风管-2400H（大） 无 | C9: 1 | D9: MDAJB241107D0005 | E9: VIC-Mel | F9: Marketing
B10: Promotional material 无 WG+分体+风管-2400H（大） 无 | C10: 1 | D10: MDAJB241107D0005 | E10: VIC-Mel | F10: Marketing
B11: Promotional material 无 WG+分体+风管-2400H（大） 无 | C11: 1 | D11: MDAJB241107D0005 | E11: VIC-Mel | F11: Marketing
B12: Promotional material 无 WG+分体+风管-2400H（大） 无 | C12: 1 | D12: MDAJB241107D0005 | E12: VIC-Mel | F12: Marketing
B13: Promotional material 无 WG+分体+风管-2400H（大） 无 | C13: 1 | D13: MDAJB241107D0005 | E13: VIC-Mel | F13: Marketing
B14: Promotional material 无 WG+分体+风管-2400H（小） 无 | C14: 1 | D14: MDAJB241107D0005 | E14: VIC-Mel | F14: Marketing
B15: Promotional material 无 WG+分体+风管-2400H（小） 无 | C15: 1 | D15: MDAJB241107D0005 | E15: VIC-Mel | F15: Marketing
B16: Promotional material 无 WG+分体+风管-2400H（小） 无 | C16: 1 | D16: MDAJB241107D0005 | E16: VIC-Mel | F16: Marketing
B17: Promotional material 无 WG+分体+风管-2400H（小） 无 | C17: 1 | D17: MDAJB241107D0005 | E17: VIC-Mel | F17: Marketing
B18: Promotional material 无 WG+分体+风管-2400H（小） 无 | C18: 1 | D18: MDAJB241107D0005 | E18: VIC-Mel | F18: Marketing
B19: Promotional material 无 XtremeSave-2400H 无 | C19: 1 | D19: MDAJB241107D0005 | E19: VIC-Mel | F19: Marketing
... B26: 工具包 | C26: 48 | D26: MDAJB241107D0005 | E26: VIC-Mel | F26: Aftersales
B27: MFAB70NB 纸箱 | C27: 1 | D27: - | E27: VIC-Mel | F27: Warehouse | H27: 补柜号：BHCU5008651里面，MFAB70NB的纸箱
B28: Nick 名片 | C28: 1 | D28: - | E28: VIC-Mel | F28: Aftersales | H28: 放在其中一箱工具包里，外箱有写：Nick名片
A29: BSIU9814155 | B29: SDA-MEC60咖箱 | C29: 10 | D29: MDAJB241126D0010 | E29: VIC-Mel | F29: Warehouse | G29: 45648 | H29: FOC
A30: TXGU6734231 | B30: 工具包 | C30: 22 | D30: - | E30: QLD-Brisbane | F30: Aftersales | G30: 45678
A31: TSSU5116615 | B31: RAC简易展架 -美的牌 | C31: 30 | D31: MDAJB250117D0014 | E31: VIC-Mel | F31: Marketing | G31: 45708 | H31: RAC 展架，6.3CBM
B32: MBT行李箱 | C32: 10 | D32: MDAJB250117D0014 | E32: VIC-Mel | F32: Marketing | H32: MBT10个行李箱
B33: 卡片（道歉卡） | C33: 2000 | D33: - | E33: VIC-Mel | F33: Aftersales | H33: 采购物料
B34: 卡片（感谢卡） | C34: 100 | D34: - | E34: VIC-Mel | F34: Aftersales | H34: 采购物料
B35: 水平卷尺 | C35: 1500 | D35: - | E35: VIC-Mel | F35: Aftersales | H35: 采购物料
B36: 纸箱 大盒 42 x 27 x 21cm 中盒 35 x 24 x 20cm 小盒 23 x15 x 5cm | C36: 3000 | D36: - | E36: VIC-Mel | F36: Aftersales | H36: 采购物料
B37: 纸箱（61x61x10cm） | C37: 100 | D37: - | E37: VIC-Mel | F37: Aftersales | H37: 采购物料
B38: 纸箱（90x18x18cm） | C38: 100 | D38: - | E38: VIC-Mel | F38: Aftersales | H38: 采购物料
B39: 笔 | C39: =2010-100 -> 1910 | D39: - | E39: VIC-Mel | F39: Marketing | H39: 采购物料
B40: 地毯 | C40: 100 | D40: - | E40: VIC-Mel | F40: Marketing | H40: 采购物料
B41: 鼠标垫 | C41: 920 | D41: - | E41: VIC-Mel | F41: Marketing | H41: 采购物料
B42: 背包 | C42: 99 | D42: - | E42: VIC-Mel | F42: Marketing | H42: 采购物料
B43: 雨伞 | C43: =800-120 -> 680 | D43: - | E43: VIC-Mel | F43: Marketing | H43: 采购物料
B44: 多功能钥匙工具 | C44: 1500 | D44: - | E44: VIC-Mel | F44: Marketing | H44: 采购物料
B45: 帆布袋 | C45: 875 | D45: - | E45: VIC-Mel | F45: Marketing | H45: 采购物料
B46: 礼品袋 | C46: 500 | D46: - | E46: VIC-Mel | F46: Marketing | H46: 采购物料
...
